  File "/home/linuxlite/Desktop/django_exam/recipes_book/manage.py", line 22, in <module>
    main()
  File "/home/linuxlite/Desktop/django_exam/recipes_book/manage.py", line 18, in main
    execute_from_command_line(sys.argv)
  File "/home/linuxlite/Desktop/django_exam/venv/lib/python3.10/site-packages/django/core/management/__init__.py", line 442, in execute_from_command_line
    utility.execute()
  File "/home/linuxlite/Desktop/django_exam/venv/lib/python3.10/site-packages/django/core/management/__init__.py", line 382, in execute
    settings.INSTALLED_APPS
  File "/home/linuxlite/Desktop/django_exam/venv/lib/python3.10/site-packages/django/conf/__init__.py", line 102, in __getattr__
    self._setup(name)
  File "/home/linuxlite/Desktop/django_exam/venv/lib/python3.10/site-packages/django/conf/__init__.py", line 89, in _setup
    self._wrapped = Settings(settings_module)
  File "/home/linuxlite/Desktop/django_exam/venv/lib/python3.10/site-packages/django/conf/__init__.py", line 217, in __init__
    mod = importlib.import_module(self.SETTINGS_MODULE)
  File "/usr/lib/python3.10/importlib/__init__.py", line 126, in import_module
    return _bootstrap._gcd_import(name[level:], package, level)
  File "<frozen importlib._bootstrap>", line 1050, in _gcd_import
  File "<frozen importlib._bootstrap>", line 1027, in _find_and_load
  File "<frozen importlib._bootstrap>", line 1006, in _find_and_load_unlocked
  File "<frozen importlib._bootstrap>", line 688, in _load_unlocked
  File "<frozen importlib._bootstrap_external>", line 883, in exec_module
  File "<frozen importlib._bootstrap>", line 241, in _call_with_frames_removed
  File "/home/linuxlite/Desktop/django_exam/recipes_book/recipes_book/settings.py", line 126, in <module>
    MEDIA_ROOT = os.path.join(BASE_DIR, 'media')
NameError: name 'os' is not defined
 linuxlite  (e) django_exam   master  ~  Desktop  django_exam  recipes_book  1  python manage.py makemigrations
Traceback (most recent call last):
  File "/home/linuxlite/Desktop/django_exam/recipes_book/manage.py", line 22, in <module>
    main()
  File "/home/linuxlite/Desktop/django_exam/recipes_book/manage.py", line 18, in main
    execute_from_command_line(sys.argv)
  File "/home/linuxlite/Desktop/django_exam/venv/lib/python3.10/site-packages/django/core/management/__init__.py", line 442, in execute_from_command_line
    utility.execute()
  File "/home/linuxlite/Desktop/django_exam/venv/lib/python3.10/site-packages/django/core/management/__init__.py", line 436, in execute
    self.fetch_command(subcommand).run_from_argv(self.argv)
  File "/home/linuxlite/Desktop/django_exam/venv/lib/python3.10/site-packages/django/core/management/base.py", line 412, in run_from_argv
    self.execute(*args, **cmd_options)
  File "/home/linuxlite/Desktop/django_exam/venv/lib/python3.10/site-packages/django/core/management/base.py", line 453, in execute
    self.check()
  File "/home/linuxlite/Desktop/django_exam/venv/lib/python3.10/site-packages/django/core/management/base.py", line 485, in check
    all_issues = checks.run_checks(
  File "/home/linuxlite/Desktop/django_exam/venv/lib/python3.10/site-packages/django/core/checks/registry.py", line 88, in run_checks
    new_errors = check(app_configs=app_configs, databases=databases)
  File "/home/linuxlite/Desktop/django_exam/venv/lib/python3.10/site-packages/django/core/checks/urls.py", line 14, in check_url_config
    return check_resolver(resolver)
  File "/home/linuxlite/Desktop/django_exam/venv/lib/python3.10/site-packages/django/core/checks/urls.py", line 24, in check_resolver
    return check_method()
  File "/home/linuxlite/Desktop/django_exam/venv/lib/python3.10/site-packages/django/urls/resolvers.py", line 494, in check
    for pattern in self.url_patterns:
  File "/home/linuxlite/Desktop/django_exam/venv/lib/python3.10/site-packages/django/utils/functional.py", line 57, in __get__
    res = instance.__dict__[self.name] = self.func(instance)
  File "/home/linuxlite/Desktop/django_exam/venv/lib/python3.10/site-packages/django/urls/resolvers.py", line 715, in url_patterns
    patterns = getattr(self.urlconf_module, "urlpatterns", self.urlconf_module)
  File "/home/linuxlite/Desktop/django_exam/venv/lib/python3.10/site-packages/django/utils/functional.py", line 57, in __get__
    res = instance.__dict__[self.name] = self.func(instance)
  File "/home/linuxlite/Desktop/django_exam/venv/lib/python3.10/site-packages/django/urls/resolvers.py", line 708, in urlconf_module
    return import_module(self.urlconf_name)
  File "/usr/lib/python3.10/importlib/__init__.py", line 126, in import_module
    return _bootstrap._gcd_import(name[level:], package, level)
  File "<frozen importlib._bootstrap>", line 1050, in _gcd_import
  File "<frozen importlib._bootstrap>", line 1027, in _find_and_load
  File "<frozen importlib._bootstrap>", line 1006, in _find_and_load_unlocked
  File "<frozen importlib._bootstrap>", line 688, in _load_unlocked
  File "<frozen importlib._bootstrap_external>", line 883, in exec_module
  File "<frozen importlib._bootstrap>", line 241, in _call_with_frames_removed
  File "/home/linuxlite/Desktop/django_exam/recipes_book/recipes_book/urls.py", line 22, in <module>
    path('', include('recipes.urls'), name='recipes'),
  File "/home/linuxlite/Desktop/django_exam/venv/lib/python3.10/site-packages/django/urls/conf.py", line 38, in include
    urlconf_module = import_module(urlconf_module)
  File "/usr/lib/python3.10/importlib/__init__.py", line 126, in import_module
    return _bootstrap._gcd_import(name[level:], package, level)
  File "<frozen importlib._bootstrap>", line 1050, in _gcd_import
  File "<frozen importlib._bootstrap>", line 1027, in _find_and_load
  File "<frozen importlib._bootstrap>", line 992, in _find_and_load_unlocked
  File "<frozen importlib._bootstrap>", line 241, in _call_with_frames_removed
  File "<frozen importlib._bootstrap>", line 1050, in _gcd_import
  File "<frozen importlib._bootstrap>", line 1027, in _find_and_load
  File "<frozen importlib._bootstrap>", line 1004, in _find_and_load_unlocked
ModuleNotFoundError: No module named 'recipes'
 linuxlite  (e) django_exam   master  ~  Desktop  django_exam  recipes_book  1  python manage.py makemigrations
Traceback (most recent call last):
  File "/home/linuxlite/Desktop/django_exam/recipes_book/manage.py", line 22, in <module>
    main()
  File "/home/linuxlite/Desktop/django_exam/recipes_book/manage.py", line 18, in main
    execute_from_command_line(sys.argv)
  File "/home/linuxlite/Desktop/django_exam/venv/lib/python3.10/site-packages/django/core/management/__init__.py", line 442, in execute_from_command_line
    utility.execute()
  File "/home/linuxlite/Desktop/django_exam/venv/lib/python3.10/site-packages/django/core/management/__init__.py", line 436, in execute
    self.fetch_command(subcommand).run_from_argv(self.argv)
  File "/home/linuxlite/Desktop/django_exam/venv/lib/python3.10/site-packages/django/core/management/base.py", line 412, in run_from_argv
    self.execute(*args, **cmd_options)
  File "/home/linuxlite/Desktop/django_exam/venv/lib/python3.10/site-packages/django/core/management/base.py", line 453, in execute
    self.check()
  File "/home/linuxlite/Desktop/django_exam/venv/lib/python3.10/site-packages/django/core/management/base.py", line 485, in check
    all_issues = checks.run_checks(
  File "/home/linuxlite/Desktop/django_exam/venv/lib/python3.10/site-packages/django/core/checks/registry.py", line 88, in run_checks
    new_errors = check(app_configs=app_configs, databases=databases)
  File "/home/linuxlite/Desktop/django_exam/venv/lib/python3.10/site-packages/django/core/checks/urls.py", line 14, in check_url_config
    return check_resolver(resolver)
  File "/home/linuxlite/Desktop/django_exam/venv/lib/python3.10/site-packages/django/core/checks/urls.py", line 24, in check_resolver
    return check_method()
  File "/home/linuxlite/Desktop/django_exam/venv/lib/python3.10/site-packages/django/urls/resolvers.py", line 494, in check
    for pattern in self.url_patterns:
  File "/home/linuxlite/Desktop/django_exam/venv/lib/python3.10/site-packages/django/utils/functional.py", line 57, in __get__
    res = instance.__dict__[self.name] = self.func(instance)
  File "/home/linuxlite/Desktop/django_exam/venv/lib/python3.10/site-packages/django/urls/resolvers.py", line 715, in url_patterns
    patterns = getattr(self.urlconf_module, "urlpatterns", self.urlconf_module)
  File "/home/linuxlite/Desktop/django_exam/venv/lib/python3.10/site-packages/django/utils/functional.py", line 57, in __get__
    res = instance.__dict__[self.name] = self.func(instance)
  File "/home/linuxlite/Desktop/django_exam/venv/lib/python3.10/site-packages/django/urls/resolvers.py", line 708, in urlconf_module
    return import_module(self.urlconf_name)
  File "/usr/lib/python3.10/importlib/__init__.py", line 126, in import_module
    return _bootstrap._gcd_import(name[level:], package, level)
  File "<frozen importlib._bootstrap>", line 1050, in _gcd_import
  File "<frozen importlib._bootstrap>", line 1027, in _find_and_load
  File "<frozen importlib._bootstrap>", line 1006, in _find_and_load_unlocked
  File "<frozen importlib._bootstrap>", line 688, in _load_unlocked
  File "<frozen importlib._bootstrap_external>", line 883, in exec_module
  File "<frozen importlib._bootstrap>", line 241, in _call_with_frames_removed
  File "/home/linuxlite/Desktop/django_exam/recipes_book/recipes_book/urls.py", line 22, in <module>
    path('', include('recipe.urls'), name='recipes'),
  File "/home/linuxlite/Desktop/django_exam/venv/lib/python3.10/site-packages/django/urls/conf.py", line 38, in include
    urlconf_module = import_module(urlconf_module)
  File "/usr/lib/python3.10/importlib/__init__.py", line 126, in import_module
    return _bootstrap._gcd_import(name[level:], package, level)
  File "<frozen importlib._bootstrap>", line 1050, in _gcd_import
  File "<frozen importlib._bootstrap>", line 1027, in _find_and_load
  File "<frozen importlib._bootstrap>", line 1006, in _find_and_load_unlocked
  File "<frozen importlib._bootstrap>", line 688, in _load_unlocked
  File "<frozen importlib._bootstrap_external>", line 883, in exec_module
  File "<frozen importlib._bootstrap>", line 241, in _call_with_frames_removed
  File "/home/linuxlite/Desktop/django_exam/recipes_book/recipe/urls.py", line 2, in <module>
    from . import views
  File "/home/linuxlite/Desktop/django_exam/recipes_book/recipe/views.py", line 7, in <module>
    from .forms import RecipeForm
  File "/home/linuxlite/Desktop/django_exam/recipes_book/recipe/forms.py", line 7, in <module>
    class RecipeForm(ModelForm):
  File "/home/linuxlite/Desktop/django_exam/venv/lib/python3.10/site-packages/django/forms/models.py", line 321, in __new__
    raise FieldError(message)
django.core.exceptions.FieldError: Unknown field(s) (title, authors) specified for Recipe
 linuxlite  (e) django_exam   master  ~  Desktop  django_exam  recipes_book  1  python manage.py makemigrations
Traceback (most recent call last):
  File "/home/linuxlite/Desktop/django_exam/recipes_book/manage.py", line 22, in <module>
    main()
  File "/home/linuxlite/Desktop/django_exam/recipes_book/manage.py", line 18, in main
    execute_from_command_line(sys.argv)
  File "/home/linuxlite/Desktop/django_exam/venv/lib/python3.10/site-packages/django/core/management/__init__.py", line 442, in execute_from_command_line
    utility.execute()
  File "/home/linuxlite/Desktop/django_exam/venv/lib/python3.10/site-packages/django/core/management/__init__.py", line 436, in execute
    self.fetch_command(subcommand).run_from_argv(self.argv)
  File "/home/linuxlite/Desktop/django_exam/venv/lib/python3.10/site-packages/django/core/management/base.py", line 412, in run_from_argv
    self.execute(*args, **cmd_options)
  File "/home/linuxlite/Desktop/django_exam/venv/lib/python3.10/site-packages/django/core/management/base.py", line 453, in execute
    self.check()
  File "/home/linuxlite/Desktop/django_exam/venv/lib/python3.10/site-packages/django/core/management/base.py", line 485, in check
    all_issues = checks.run_checks(
  File "/home/linuxlite/Desktop/django_exam/venv/lib/python3.10/site-packages/django/core/checks/registry.py", line 88, in run_checks
    new_errors = check(app_configs=app_configs, databases=databases)
  File "/home/linuxlite/Desktop/django_exam/venv/lib/python3.10/site-packages/django/core/checks/urls.py", line 14, in check_url_config
    return check_resolver(resolver)
  File "/home/linuxlite/Desktop/django_exam/venv/lib/python3.10/site-packages/django/core/checks/urls.py", line 24, in check_resolver
    return check_method()
  File "/home/linuxlite/Desktop/django_exam/venv/lib/python3.10/site-packages/django/urls/resolvers.py", line 494, in check
    for pattern in self.url_patterns:
  File "/home/linuxlite/Desktop/django_exam/venv/lib/python3.10/site-packages/django/utils/functional.py", line 57, in __get__
    res = instance.__dict__[self.name] = self.func(instance)
  File "/home/linuxlite/Desktop/django_exam/venv/lib/python3.10/site-packages/django/urls/resolvers.py", line 715, in url_patterns
    patterns = getattr(self.urlconf_module, "urlpatterns", self.urlconf_module)
  File "/home/linuxlite/Desktop/django_exam/venv/lib/python3.10/site-packages/django/utils/functional.py", line 57, in __get__
    res = instance.__dict__[self.name] = self.func(instance)
  File "/home/linuxlite/Desktop/django_exam/venv/lib/python3.10/site-packages/django/urls/resolvers.py", line 708, in urlconf_module
    return import_module(self.urlconf_name)
  File "/usr/lib/python3.10/importlib/__init__.py", line 126, in import_module
    return _bootstrap._gcd_import(name[level:], package, level)
  File "<frozen importlib._bootstrap>", line 1050, in _gcd_import
  File "<frozen importlib._bootstrap>", line 1027, in _find_and_load
  File "<frozen importlib._bootstrap>", line 1006, in _find_and_load_unlocked
  File "<frozen importlib._bootstrap>", line 688, in _load_unlocked
  File "<frozen importlib._bootstrap_external>", line 883, in exec_module
  File "<frozen importlib._bootstrap>", line 241, in _call_with_frames_removed
  File "/home/linuxlite/Desktop/django_exam/recipes_book/recipes_book/urls.py", line 22, in <module>
    path('', include('recipe.urls'), name='recipe'),
  File "/home/linuxlite/Desktop/django_exam/venv/lib/python3.10/site-packages/django/urls/conf.py", line 38, in include
    urlconf_module = import_module(urlconf_module)
  File "/usr/lib/python3.10/importlib/__init__.py", line 126, in import_module
    return _bootstrap._gcd_import(name[level:], package, level)
  File "<frozen importlib._bootstrap>", line 1050, in _gcd_import
  File "<frozen importlib._bootstrap>", line 1027, in _find_and_load
  File "<frozen importlib._bootstrap>", line 1006, in _find_and_load_unlocked
  File "<frozen importlib._bootstrap>", line 688, in _load_unlocked
  File "<frozen importlib._bootstrap_external>", line 883, in exec_module
  File "<frozen importlib._bootstrap>", line 241, in _call_with_frames_removed
  File "/home/linuxlite/Desktop/django_exam/recipes_book/recipe/urls.py", line 2, in <module>
    from . import views
  File "/home/linuxlite/Desktop/django_exam/recipes_book/recipe/views.py", line 7, in <module>
    from .forms import RecipeForm
  File "/home/linuxlite/Desktop/django_exam/recipes_book/recipe/forms.py", line 7, in <module>
    class RecipeForm(ModelForm):
  File "/home/linuxlite/Desktop/django_exam/venv/lib/python3.10/site-packages/django/forms/models.py", line 321, in __new__
    raise FieldError(message)
django.core.exceptions.FieldError: Unknown field(s) (authors, title) specified for Recipe
 linuxlite  (e) django_exam   master  ~  Desktop  django_exam  recipes_book  1  сдуфт
сдуфт: command not found
 linuxlite  (e) django_exam   master  ~  Desktop  django_exam  recipes_book  127  clear
 linuxlite  (e) django_exam   master  ~  Desktop  django_exam  recipes_book  python manage.py makemigrations
Traceback (most recent call last):
  File "/home/linuxlite/Desktop/django_exam/recipes_book/manage.py", line 22, in <module>
    main()
  File "/home/linuxlite/Desktop/django_exam/recipes_book/manage.py", line 18, in main
    execute_from_command_line(sys.argv)
  File "/home/linuxlite/Desktop/django_exam/venv/lib/python3.10/site-packages/django/core/management/__init__.py", line 442, in execute_from_command_line
    utility.execute()
  File "/home/linuxlite/Desktop/django_exam/venv/lib/python3.10/site-packages/django/core/management/__init__.py", line 436, in execute
    self.fetch_command(subcommand).run_from_argv(self.argv)
  File "/home/linuxlite/Desktop/django_exam/venv/lib/python3.10/site-packages/django/core/management/base.py", line 412, in run_from_argv
    self.execute(*args, **cmd_options)
  File "/home/linuxlite/Desktop/django_exam/venv/lib/python3.10/site-packages/django/core/management/base.py", line 453, in execute
    self.check()
  File "/home/linuxlite/Desktop/django_exam/venv/lib/python3.10/site-packages/django/core/management/base.py", line 485, in check
    all_issues = checks.run_checks(
  File "/home/linuxlite/Desktop/django_exam/venv/lib/python3.10/site-packages/django/core/checks/registry.py", line 88, in run_checks
    new_errors = check(app_configs=app_configs, databases=databases)
  File "/home/linuxlite/Desktop/django_exam/venv/lib/python3.10/site-packages/django/core/checks/urls.py", line 14, in check_url_config
    return check_resolver(resolver)
  File "/home/linuxlite/Desktop/django_exam/venv/lib/python3.10/site-packages/django/core/checks/urls.py", line 24, in check_resolver
    return check_method()
  File "/home/linuxlite/Desktop/django_exam/venv/lib/python3.10/site-packages/django/urls/resolvers.py", line 494, in check
    for pattern in self.url_patterns:
  File "/home/linuxlite/Desktop/django_exam/venv/lib/python3.10/site-packages/django/utils/functional.py", line 57, in __get__
    res = instance.__dict__[self.name] = self.func(instance)
  File "/home/linuxlite/Desktop/django_exam/venv/lib/python3.10/site-packages/django/urls/resolvers.py", line 715, in url_patterns
    patterns = getattr(self.urlconf_module, "urlpatterns", self.urlconf_module)
  File "/home/linuxlite/Desktop/django_exam/venv/lib/python3.10/site-packages/django/utils/functional.py", line 57, in __get__
    res = instance.__dict__[self.name] = self.func(instance)
  File "/home/linuxlite/Desktop/django_exam/venv/lib/python3.10/site-packages/django/urls/resolvers.py", line 708, in urlconf_module
    return import_module(self.urlconf_name)
  File "/usr/lib/python3.10/importlib/__init__.py", line 126, in import_module
    return _bootstrap._gcd_import(name[level:], package, level)
  File "<frozen importlib._bootstrap>", line 1050, in _gcd_import
  File "<frozen importlib._bootstrap>", line 1027, in _find_and_load
  File "<frozen importlib._bootstrap>", line 1006, in _find_and_load_unlocked
  File "<frozen importlib._bootstrap>", line 688, in _load_unlocked
  File "<frozen importlib._bootstrap_external>", line 883, in exec_module
  File "<frozen importlib._bootstrap>", line 241, in _call_with_frames_removed
  File "/home/linuxlite/Desktop/django_exam/recipes_book/recipes_book/urls.py", line 22, in <module>
    path('', include('recipe.urls'), name='recipe'),
  File "/home/linuxlite/Desktop/django_exam/venv/lib/python3.10/site-packages/django/urls/conf.py", line 38, in include
    urlconf_module = import_module(urlconf_module)
  File "/usr/lib/python3.10/importlib/__init__.py", line 126, in import_module
    return _bootstrap._gcd_import(name[level:], package, level)
  File "<frozen importlib._bootstrap>", line 1050, in _gcd_import
  File "<frozen importlib._bootstrap>", line 1027, in _find_and_load
  File "<frozen importlib._bootstrap>", line 1006, in _find_and_load_unlocked
  File "<frozen importlib._bootstrap>", line 688, in _load_unlocked
  File "<frozen importlib._bootstrap_external>", line 883, in exec_module
  File "<frozen importlib._bootstrap>", line 241, in _call_with_frames_removed
  File "/home/linuxlite/Desktop/django_exam/recipes_book/recipe/urls.py", line 2, in <module>
    from . import views
  File "/home/linuxlite/Desktop/django_exam/recipes_book/recipe/views.py", line 7, in <module>
    from .forms import RecipeForm
  File "/home/linuxlite/Desktop/django_exam/recipes_book/recipe/forms.py", line 7, in <module>
    class RecipeForm(ModelForm):
  File "/home/linuxlite/Desktop/django_exam/venv/lib/python3.10/site-packages/django/forms/models.py", line 321, in __new__
    raise FieldError(message)
django.core.exceptions.FieldError: Unknown field(s) (authors, title) specified for Recipe
 linuxlite  (e) django_exam   master  ~  Desktop  django_exam  recipes_book  1  python manage.py makemigrations
Traceback (most recent call last):
  File "/home/linuxlite/Desktop/django_exam/recipes_book/manage.py", line 22, in <module>
    main()
  File "/home/linuxlite/Desktop/django_exam/recipes_book/manage.py", line 18, in main
    execute_from_command_line(sys.argv)
  File "/home/linuxlite/Desktop/django_exam/venv/lib/python3.10/site-packages/django/core/management/__init__.py", line 442, in execute_from_command_line
    utility.execute()
  File "/home/linuxlite/Desktop/django_exam/venv/lib/python3.10/site-packages/django/core/management/__init__.py", line 436, in execute
    self.fetch_command(subcommand).run_from_argv(self.argv)
  File "/home/linuxlite/Desktop/django_exam/venv/lib/python3.10/site-packages/django/core/management/base.py", line 412, in run_from_argv
    self.execute(*args, **cmd_options)
  File "/home/linuxlite/Desktop/django_exam/venv/lib/python3.10/site-packages/django/core/management/base.py", line 453, in execute
    self.check()
  File "/home/linuxlite/Desktop/django_exam/venv/lib/python3.10/site-packages/django/core/management/base.py", line 485, in check
    all_issues = checks.run_checks(
  File "/home/linuxlite/Desktop/django_exam/venv/lib/python3.10/site-packages/django/core/checks/registry.py", line 88, in run_checks
    new_errors = check(app_configs=app_configs, databases=databases)
  File "/home/linuxlite/Desktop/django_exam/venv/lib/python3.10/site-packages/django/core/checks/urls.py", line 14, in check_url_config
    return check_resolver(resolver)
  File "/home/linuxlite/Desktop/django_exam/venv/lib/python3.10/site-packages/django/core/checks/urls.py", line 24, in check_resolver
    return check_method()
  File "/home/linuxlite/Desktop/django_exam/venv/lib/python3.10/site-packages/django/urls/resolvers.py", line 494, in check
    for pattern in self.url_patterns:
  File "/home/linuxlite/Desktop/django_exam/venv/lib/python3.10/site-packages/django/utils/functional.py", line 57, in __get__
    res = instance.__dict__[self.name] = self.func(instance)
  File "/home/linuxlite/Desktop/django_exam/venv/lib/python3.10/site-packages/django/urls/resolvers.py", line 715, in url_patterns
    patterns = getattr(self.urlconf_module, "urlpatterns", self.urlconf_module)
  File "/home/linuxlite/Desktop/django_exam/venv/lib/python3.10/site-packages/django/utils/functional.py", line 57, in __get__
    res = instance.__dict__[self.name] = self.func(instance)
  File "/home/linuxlite/Desktop/django_exam/venv/lib/python3.10/site-packages/django/urls/resolvers.py", line 708, in urlconf_module
    return import_module(self.urlconf_name)
  File "/usr/lib/python3.10/importlib/__init__.py", line 126, in import_module
    return _bootstrap._gcd_import(name[level:], package, level)
  File "<frozen importlib._bootstrap>", line 1050, in _gcd_import
  File "<frozen importlib._bootstrap>", line 1027, in _find_and_load
  File "<frozen importlib._bootstrap>", line 1006, in _find_and_load_unlocked
  File "<frozen importlib._bootstrap>", line 688, in _load_unlocked
  File "<frozen importlib._bootstrap_external>", line 883, in exec_module
  File "<frozen importlib._bootstrap>", line 241, in _call_with_frames_removed
  File "/home/linuxlite/Desktop/django_exam/recipes_book/recipes_book/urls.py", line 23, in <module>
    path('', include('recipe.urls')),
  File "/home/linuxlite/Desktop/django_exam/venv/lib/python3.10/site-packages/django/urls/conf.py", line 38, in include
    urlconf_module = import_module(urlconf_module)
  File "/usr/lib/python3.10/importlib/__init__.py", line 126, in import_module
    return _bootstrap._gcd_import(name[level:], package, level)
  File "<frozen importlib._bootstrap>", line 1050, in _gcd_import
  File "<frozen importlib._bootstrap>", line 1027, in _find_and_load
  File "<frozen importlib._bootstrap>", line 1006, in _find_and_load_unlocked
  File "<frozen importlib._bootstrap>", line 688, in _load_unlocked
  File "<frozen importlib._bootstrap_external>", line 883, in exec_module
  File "<frozen importlib._bootstrap>", line 241, in _call_with_frames_removed
  File "/home/linuxlite/Desktop/django_exam/recipes_book/recipe/urls.py", line 2, in <module>
    from . import views
  File "/home/linuxlite/Desktop/django_exam/recipes_book/recipe/views.py", line 7, in <module>
    from .forms import RecipeForm
  File "/home/linuxlite/Desktop/django_exam/recipes_book/recipe/forms.py", line 7, in <module>
    class RecipeForm(ModelForm):
  File "/home/linuxlite/Desktop/django_exam/venv/lib/python3.10/site-packages/django/forms/models.py", line 321, in __new__
    raise FieldError(message)
django.core.exceptions.FieldError: Unknown field(s) (title, authors) specified for Recipe
 linuxlite  (e) django_exam   master  ~  Desktop  django_exam  recipes_book  1  clear
 linuxlite  (e) django_exam   master  ~  Desktop  django_exam  recipes_book  python manage.py makemigrations
Traceback (most recent call last):
  File "/home/linuxlite/Desktop/django_exam/recipes_book/manage.py", line 22, in <module>
    main()
  File "/home/linuxlite/Desktop/django_exam/recipes_book/manage.py", line 18, in main
    execute_from_command_line(sys.argv)
  File "/home/linuxlite/Desktop/django_exam/venv/lib/python3.10/site-packages/django/core/management/__init__.py", line 442, in execute_from_command_line
    utility.execute()
  File "/home/linuxlite/Desktop/django_exam/venv/lib/python3.10/site-packages/django/core/management/__init__.py", line 436, in execute
    self.fetch_command(subcommand).run_from_argv(self.argv)
  File "/home/linuxlite/Desktop/django_exam/venv/lib/python3.10/site-packages/django/core/management/base.py", line 412, in run_from_argv
    self.execute(*args, **cmd_options)
  File "/home/linuxlite/Desktop/django_exam/venv/lib/python3.10/site-packages/django/core/management/base.py", line 453, in execute
    self.check()
  File "/home/linuxlite/Desktop/django_exam/venv/lib/python3.10/site-packages/django/core/management/base.py", line 485, in check
    all_issues = checks.run_checks(
  File "/home/linuxlite/Desktop/django_exam/venv/lib/python3.10/site-packages/django/core/checks/registry.py", line 88, in run_checks
    new_errors = check(app_configs=app_configs, databases=databases)
  File "/home/linuxlite/Desktop/django_exam/venv/lib/python3.10/site-packages/django/core/checks/urls.py", line 14, in check_url_config
    return check_resolver(resolver)
  File "/home/linuxlite/Desktop/django_exam/venv/lib/python3.10/site-packages/django/core/checks/urls.py", line 24, in check_resolver
    return check_method()
  File "/home/linuxlite/Desktop/django_exam/venv/lib/python3.10/site-packages/django/urls/resolvers.py", line 494, in check
    for pattern in self.url_patterns:
  File "/home/linuxlite/Desktop/django_exam/venv/lib/python3.10/site-packages/django/utils/functional.py", line 57, in __get__
    res = instance.__dict__[self.name] = self.func(instance)
  File "/home/linuxlite/Desktop/django_exam/venv/lib/python3.10/site-packages/django/urls/resolvers.py", line 715, in url_patterns
    patterns = getattr(self.urlconf_module, "urlpatterns", self.urlconf_module)
  File "/home/linuxlite/Desktop/django_exam/venv/lib/python3.10/site-packages/django/utils/functional.py", line 57, in __get__
    res = instance.__dict__[self.name] = self.func(instance)
  File "/home/linuxlite/Desktop/django_exam/venv/lib/python3.10/site-packages/django/urls/resolvers.py", line 708, in urlconf_module
    return import_module(self.urlconf_name)
  File "/usr/lib/python3.10/importlib/__init__.py", line 126, in import_module
    return _bootstrap._gcd_import(name[level:], package, level)
  File "<frozen importlib._bootstrap>", line 1050, in _gcd_import
  File "<frozen importlib._bootstrap>", line 1027, in _find_and_load
  File "<frozen importlib._bootstrap>", line 1006, in _find_and_load_unlocked
  File "<frozen importlib._bootstrap>", line 688, in _load_unlocked
  File "<frozen importlib._bootstrap_external>", line 883, in exec_module
  File "<frozen importlib._bootstrap>", line 241, in _call_with_frames_removed
  File "/home/linuxlite/Desktop/django_exam/recipes_book/recipes_book/urls.py", line 23, in <module>
    path('', include('recipe.urls')),
  File "/home/linuxlite/Desktop/django_exam/venv/lib/python3.10/site-packages/django/urls/conf.py", line 38, in include
    urlconf_module = import_module(urlconf_module)
  File "/usr/lib/python3.10/importlib/__init__.py", line 126, in import_module
    return _bootstrap._gcd_import(name[level:], package, level)
  File "<frozen importlib._bootstrap>", line 1050, in _gcd_import
  File "<frozen importlib._bootstrap>", line 1027, in _find_and_load
  File "<frozen importlib._bootstrap>", line 1006, in _find_and_load_unlocked
  File "<frozen importlib._bootstrap>", line 688, in _load_unlocked
  File "<frozen importlib._bootstrap_external>", line 883, in exec_module
  File "<frozen importlib._bootstrap>", line 241, in _call_with_frames_removed
  File "/home/linuxlite/Desktop/django_exam/recipes_book/recipe/urls.py", line 2, in <module>
    from . import views
  File "/home/linuxlite/Desktop/django_exam/recipes_book/recipe/views.py", line 7, in <module>
    from .forms import RecipeForm
  File "/home/linuxlite/Desktop/django_exam/recipes_book/recipe/forms.py", line 7, in <module>
    class RecipeForm(ModelForm):
  File "/home/linuxlite/Desktop/django_exam/venv/lib/python3.10/site-packages/django/forms/models.py", line 321, in __new__
    raise FieldError(message)
django.core.exceptions.FieldError: Unknown field(s) (authors, title) specified for Recipe
 linuxlite  (e) django_exam   master  ~  Desktop  django_exam  recipes_book  1  clear
 linuxlite  (e) django_exam   master  ~  Desktop  django_exam  recipes_book  python manage.py makemigrations
Traceback (most recent call last):
  File "/home/linuxlite/Desktop/django_exam/recipes_book/manage.py", line 22, in <module>
    main()
  File "/home/linuxlite/Desktop/django_exam/recipes_book/manage.py", line 18, in main
    execute_from_command_line(sys.argv)
  File "/home/linuxlite/Desktop/django_exam/venv/lib/python3.10/site-packages/django/core/management/__init__.py", line 442, in execute_from_command_line
    utility.execute()
  File "/home/linuxlite/Desktop/django_exam/venv/lib/python3.10/site-packages/django/core/management/__init__.py", line 436, in execute
    self.fetch_command(subcommand).run_from_argv(self.argv)
  File "/home/linuxlite/Desktop/django_exam/venv/lib/python3.10/site-packages/django/core/management/base.py", line 412, in run_from_argv
    self.execute(*args, **cmd_options)
  File "/home/linuxlite/Desktop/django_exam/venv/lib/python3.10/site-packages/django/core/management/base.py", line 453, in execute
    self.check()
  File "/home/linuxlite/Desktop/django_exam/venv/lib/python3.10/site-packages/django/core/management/base.py", line 485, in check
    all_issues = checks.run_checks(
  File "/home/linuxlite/Desktop/django_exam/venv/lib/python3.10/site-packages/django/core/checks/registry.py", line 88, in run_checks
    new_errors = check(app_configs=app_configs, databases=databases)
  File "/home/linuxlite/Desktop/django_exam/venv/lib/python3.10/site-packages/django/core/checks/urls.py", line 14, in check_url_config
    return check_resolver(resolver)
  File "/home/linuxlite/Desktop/django_exam/venv/lib/python3.10/site-packages/django/core/checks/urls.py", line 24, in check_resolver
    return check_method()
  File "/home/linuxlite/Desktop/django_exam/venv/lib/python3.10/site-packages/django/urls/resolvers.py", line 494, in check
    for pattern in self.url_patterns:
  File "/home/linuxlite/Desktop/django_exam/venv/lib/python3.10/site-packages/django/utils/functional.py", line 57, in __get__
    res = instance.__dict__[self.name] = self.func(instance)
  File "/home/linuxlite/Desktop/django_exam/venv/lib/python3.10/site-packages/django/urls/resolvers.py", line 715, in url_patterns
    patterns = getattr(self.urlconf_module, "urlpatterns", self.urlconf_module)
  File "/home/linuxlite/Desktop/django_exam/venv/lib/python3.10/site-packages/django/utils/functional.py", line 57, in __get__
    res = instance.__dict__[self.name] = self.func(instance)
  File "/home/linuxlite/Desktop/django_exam/venv/lib/python3.10/site-packages/django/urls/resolvers.py", line 708, in urlconf_module
    return import_module(self.urlconf_name)
  File "/usr/lib/python3.10/importlib/__init__.py", line 126, in import_module
    return _bootstrap._gcd_import(name[level:], package, level)
  File "<frozen importlib._bootstrap>", line 1050, in _gcd_import
  File "<frozen importlib._bootstrap>", line 1027, in _find_and_load
  File "<frozen importlib._bootstrap>", line 1006, in _find_and_load_unlocked
  File "<frozen importlib._bootstrap>", line 688, in _load_unlocked
  File "<frozen importlib._bootstrap_external>", line 883, in exec_module
  File "<frozen importlib._bootstrap>", line 241, in _call_with_frames_removed
  File "/home/linuxlite/Desktop/django_exam/recipes_book/recipes_book/urls.py", line 23, in <module>
    path('', include('recipe.urls')),
  File "/home/linuxlite/Desktop/django_exam/venv/lib/python3.10/site-packages/django/urls/conf.py", line 38, in include
    urlconf_module = import_module(urlconf_module)
  File "/usr/lib/python3.10/importlib/__init__.py", line 126, in import_module
    return _bootstrap._gcd_import(name[level:], package, level)
  File "<frozen importlib._bootstrap>", line 1050, in _gcd_import
  File "<frozen importlib._bootstrap>", line 1027, in _find_and_load
  File "<frozen importlib._bootstrap>", line 1006, in _find_and_load_unlocked
  File "<frozen importlib._bootstrap>", line 688, in _load_unlocked
  File "<frozen importlib._bootstrap_external>", line 883, in exec_module
  File "<frozen importlib._bootstrap>", line 241, in _call_with_frames_removed
  File "/home/linuxlite/Desktop/django_exam/recipes_book/recipe/urls.py", line 2, in <module>
    from . import views
  File "/home/linuxlite/Desktop/django_exam/recipes_book/recipe/views.py", line 7, in <module>
    from .forms import RecipeForm
  File "/home/linuxlite/Desktop/django_exam/recipes_book/recipe/forms.py", line 7, in <module>
    class RecipeForm(ModelForm):
  File "/home/linuxlite/Desktop/django_exam/venv/lib/python3.10/site-packages/django/forms/models.py", line 321, in __new__
    raise FieldError(message)
django.core.exceptions.FieldError: Unknown field(s) (authors, title) specified for Recipe


# в чем ошибка?

# models.py

from django.db import models
from django.contrib.auth.models import User
from django.urls import reverse


class Recipe(models.Model):
    title = models.CharField(max_length=100)
    authors = models.ForeignKey(User, on_delete=models.CASCADE)
    description = models.TextField()
    ingredients = models.TextField()
    time = models.IntegerField()
    image = models.ImageField(upload_to='recipe_images', blank=True)

    def __str__(self):
        return self.title

    def get_absolute_url(self):
        return reverse('recipe_detail', args=[str(self.id)])


# forms.py

from django.forms import ModelForm
from .models import Recipe


class RecipeForm(ModelForm):
    class Meta:
        model = Recipe
        fields = ['title', 'authors', 'description', 'ingredients', 'time', 'image']


# views.py

from django.shortcuts import render
from django.views.generic import ListView, DetailView, CreateView, UpdateView, DeleteView
from .models import Recipe
from .forms import RecipeForm
from django.urls import reverse_lazy


class RecipeListView(ListView):
    model = Recipe
    template_name = 'recipe_list.html'


class RecipeDetailView(DetailView):
    model = Recipe
    template_name = 'recipe_detail.html'


class RecipeCreateView(CreateView):
    model = Recipe
    form_class = RecipeForm
    template_name = 'recipe_new.html'
    success_url = reverse_lazy('recipe_list')


class RecipeUpdateView(UpdateView):
    model = Recipe
    form_class = RecipeForm
    template_name = 'recipe_edit.html'
    success_url = reverse_lazy('recipe_list')


class RecipeDeleteView(DeleteView):
